Workbook

Sheet Overzicht
A1: PARADISE — werkpakket 1
A6: Blad | B6: Totaal | C6: Te doen | D6: Bezig | E6: Klaar | F6: Geblokkeerd | G6: Vervalt | H6: Klaar (%)
A7: Taken | B7: =COUNTA(Taken!$H$5:$H$79) -> 66 | C7: =COUNTIF(Taken!$H$5:$H$79,"Te doen") -> 55 | D7: =COUNTIF(Taken!$H$5:$H$79,"Bezig") -> 2 | E7: =COUNTIF(Taken!$H$5:$H$79,"Klaar") -> 9 | F7: =COUNTIF(Taken!$H$5:$H$79,"Geblokkeerd") -> 0 | G7: =COUNTIF(Taken!$H$5:$H$79,"Vervalt") -> 0 | H7: =IF(B7=0,"",ROUND(E7/B7*100,0)) -> 14
A8: Openstaande punten | B8: =COUNTA('Openstaande punten'!$F$5:$F$37) -> 27 | C8: =COUNTIF('Openstaande punten'!$F$5:$F$37,"Te doen") -> 5 | D8: =COUNTIF('Openstaande punten'!$F$5:$F$37,"Bezig") -> 3 | E8: =COUNTIF('Openstaande punten'!$F$5:$F$37,"Klaar") -> 16 | F8: =COUNTIF('Openstaande punten'!$F$5:$F$37,"Geblokkeerd") -> 0 | G8: =COUNTIF('Openstaande punten'!$F$5:$F$37,"Vervalt") -> 3 | H8: =IF(B8=0,"",ROUND(E8/B8*100,0)) -> 59
A9: Go-NoGo | B9: =COUNTA('Go-NoGo'!$E$5:$E$12) -> 7 | C9: =COUNTIF('Go-NoGo'!$E$5:$E$12,"Te doen") -> 6 | D9: =COUNTIF('Go-NoGo'!$E$5:$E$12,"Bezig") -> 1 | E9: =COUNTIF('Go-NoGo'!$E$5:$E$12,"Klaar") -> 0 | F9: =COUNTIF('Go-NoGo'!$E$5:$E$12,"Geblokkeerd") -> 0 | G9: =COUNTIF('Go-NoGo'!$E$5:$E$12,"Vervalt") -> 0 | H9: =IF(B9=0,"",ROUND(E9/B9*100,0)) -> 0
A10: Mijlpalen | B10: =COUNTA(Mijlpalen!$F$5:$F$11) -> 7 | C10: =COUNTIF(Mijlpalen!$F$5:$F$11,"Te doen") -> 7 | D10: =COUNTIF(Mijlpalen!$F$5:$F$11,"Bezig") -> 0 | E10: =COUNTIF(Mijlpalen!$F$5:$F$11,"Klaar") -> 0 | F10: =COUNTIF(Mijlpalen!$F$5:$F$11,"Geblokkeerd") -> 0 | G10: =COUNTIF(Mijlpalen!$F$5:$F$11,"Vervalt") -> 0 | H10: =IF(B10=0,"",ROUND(E10/B10*100,0)) -> 0
A11: Alles samen | B11: =SUM(B7:B10) -> 107 | C11: =SUM(C7:C10) -> 73 | D11: =SUM(D7:D10) -> 6 | E11: =SUM(E7:E10) -> 25 | F11: =SUM(F7:F10) -> 0 | G11: =SUM(G7:G10) -> 3 | H11: =IF(B11=0,"",ROUND(E11/B11*100,0)) -> 23
A12: Statuswaarden: Te doen · Bezig · Klaar · Geblokkeerd · Vervalt

Sheet Taken
A1: Werkpakket 1 — taken en deelactiviteiten
A2: De acht taken uit de FWO-aanvraag, met de deelactiviteiten uit het operationele draaiboek. Maanden geteld vanaf september 2026.
A4: Nr | B4: Taak | C4: Wat er moet gebeuren | D4: Maanden | E4: Kalender | F4: Deliverable | G4: Wie | H4: Status | I4: Opmerking
A5: Taak 1.1 — Ethische indiening en registratie · M1–5 · D1.1 · kritisch pad
A6: 1.1a | B6: Centrale indiening | C6: Clinical investigation plan, toestemmingsformulieren, patiëntmateriaal en investigator's brochure indienen bij EC UZ Leuven, het FAGG en de zes lokale commissies | D6: 1–2 | E6: sep – okt 26 | F6: D1.1 | G6: PhD-A + Deschamps | H6: Bezig | I6: CTC en FAGG nog te doen
A7: 1.1b | B7: Toestemmingsformulieren | C7: Nederlands op maximaal B1-niveau, met GDPR-clausules; ook de deelnemende therapeuten tekenen | D7: 1–2 | E7: sep – okt 26 | F7: D1.1 | G7: PhD-A | H7: Klaar | I7: Bijlage 3 samengesteld op 10 sep
A8: 1.1c | B8: Verzekering | C8: Foutloze aansprakelijkheid van de sponsor volgens de wet van 7 mei 2004, gedekt via polis | D8: 1–2 | E8: sep – okt 26 | F8: D1.1 | G8: KU Leuven rechtsdienst | H8: Te doen | I8: ?
A9: 1.1d | B9: Wettelijk kader vastleggen | C9: ISO 14155:2020 · Verordening 2017/745 · Verordening 2016/679 · wet 22 dec 2020 · KB 18 mei 2021 · wet 22 aug 2002 · Helsinki · ICH-GCP E6(R3) | D9: 1 | E9: sep 26 | F9: D1.1 | G9: PhD-A | H9: Klaar
A10: 1.1e | B10: Monitoringopzet laten bevestigen | C10: Het coördinerende comité moet de opzet en de verenigbaarheid met ISO 14155 en ICH-GCP E6 bevestigen vóór de indiening | D10: 1–2 | E10: sep – okt 26 | F10: D1.1 | G10: Coördinerend comité | H10: Te doen | I10: Openstaand punt 25
A11: 1.1f | B11: Zes lokale goedkeuringen | C11: Per centrum indienen na de centrale beslissing, binnen dertig dagen | D11: 2–5 | E11: okt 26 – jan 27 | F11: D1.1 | G11: PhD-A + site-PI | H11: Bezig
A12: 1.1g | B12: Site Agreements | C12: Per ziekenhuis, opgesteld met de juridische dienst | D12: 2–5 | E12: okt 26 – jan 27 | F12: D1.1 | G12: KU Leuven juridisch | H12: Klaar
A13: 1.1h | B13: Subsidiecontracten | C13: KU Leuven met elk partnerziekenhuis | D13: 2–5 | E13: okt 26 – jan 27 | F13: D1.1 | G13: KU Leuven | H13: Klaar
A14: 1.1i | B14: Studieregistratie | C14: ClinicalTrials.gov en BELCRI, vóór de eerste deelnemer. Vult meteen drie blanco velden in het manuscript | D14: 2 | E14: okt 26 | F14: D1.1 | G14: PhD-A | H14: Te doen | I14: Openstaand punt 21
A15: 1.1j | B15: Verwerkersovereenkomsten | C15: Per centrum, plus aanmelding bij de DPO en een datastroomdiagram | D15: 2–3 | E15: okt – nov 26 | F15: D1.1 | G15: DPO + PhD-A | H15: Klaar
A16: 1.1k | B16: Bewaartermijn vastleggen | C16: Tien of vijftien jaar — de twee manuscriptversies spreken elkaar tegen | D16: 2 | E16: okt 26 | F16: D1.1 | G16: PhD-A | H16: Te doen | I16: Openstaand punt 10
A17: Taak 1.2 — Assessment booklet · M1–5 · D1.2 · MS1
A18: 1.2a | B18: Gebruiksrechten instrumenten | C18: NAFF, HLS-EU-6, EQ-5D-5L (licentie EuroQol), iMCQ en iPCQ (iMTA), MOS-revised, slijtageschaal — met copyright-log | D18: 1–2 | E18: sep – okt 26 | F18: D1.2 | G18: PhD-A | H18: Te doen | I18: Register to use a EuroQol instrument - EuroQol https://www.imta.nl/questionnaires/imcq/register/?utm_source=chatgpt.com
A19: 1.2b | B19: CRF-set | C19: Volgens tabel 2 van het manuscript; papieren bronformulieren, daarna overzetten naar het elektronische CRF | D19: 2–4 | E19: okt – dec 26 | F19: D1.2 | G19: PhD-A + PhD-B | H19: Te doen
A20: 1.2c | B20: Folder dagelijkse voetzorg | C20: Het document dat de patiënt mee naar huis krijgt | D20: 2–4 | E20: okt – dec 26 | F20: D1.2 | G20: PhD-A | H20: Klaar | I20: 48_Voetzorgfolder bestaat
A21: 1.2d | B21: Educatiekaart schoeisel | C21: Binnen én buiten dragen, visueel schema | D21: 2–4 | E21: okt – dec 26 | F21: D1.2 | G21: PhD-A | H21: Te doen
A22: 1.2e | B22: Uitlegfiche Orthotimer | C22: Framing als 'uw sensor': enkel temperatuur, geen GPS, geluid of camera | D22: 2–4 | E22: okt – dec 26 | F22: D1.2 | G22: PhD-A | H22: Klaar
A23: 1.2f | B23: Feedbacksjabloon therapietrouw | C23: Visuele weergave van de sensordata voor stap 3 en 4 | D23: 2–4 | E23: okt – dec 26 | F23: D1.2 | G23: PhD-A | H23: Te doen
A24: 1.2g | B24: Leesbaarheidstest | C24: Maximaal B1-niveau, bij drie pilootpatiënten | D24: 4 | E24: dec 26 | F24: D1.2 | G24: PhD-A + Diabetes Liga | H24: Te doen
A25: 1.2h | B25: Consensusvergadering | C25: Pre-read twee weken vooraf, per instrument een kwartier, ondertekende notulen | D25: 4 | E25: dec 26 | F25: D1.2 | G25: Deschamps + partners | H25: Te doen | I25: Levert MS1
A26: Taak 1.3 — Protocollen voor Usual en Optimal Care · M1–5 · D1.3
A27: SOP-1 | B27: Voetscreening en IWGDF-classificatie | C27: Onderzoeksvolgorde, afkappunten, fotografieprotocol, beslisboom, inter-rater reliability κ ≥ 0,80 | D27: 2 | E27: okt 26 | F27: D1.3 | G27: PhD-A + podoloog + KU Leuven | H27: Te doen
A28: SOP-2 | B28: Plantaire drukmeting | C28: Pedar als klinisch toestel met trublu-kalibratie; F-Scan GO alleen studieteam; acht regio's; alles in-shoe, zónder én mét de zool gemeten; norm < 200 kPa mét de zool óf ≥ 25% lager dan zonder de zool in dezelfde sessie, tot drie aanpassingen; behaalde reductie als fidelity-maat | D28: 2–3 | E28: okt – nov 26 | F28: D1.3 | G28: PhD-A + technoloog | H28: Te doen | I28: Werkinstructie pedar ontbreekt — punt 16
A29: SOP-3 | B29: Schoeisel, CMFO en Orthotimer | C29: Opbouw per schoentype, mediale steun 3-5 mm, metatarsaalbalk 9-10 mm, deklaag, pasvorm binnen én buiten met fotodocumentatie | D29: 2–3 | E29: okt – nov 26 | F29: D1.3 | G29: Pedorthist + PhD-A | H29: Klaar
A30: SOP-4 | B30: Uitlezen en therapietrouwnorm | C30: Waaktijd als noemer, 80% als responderdrempel, tussenresultaat tonen in uren | D30: 3 | E30: nov 26 | F30: D1.3 | G30: PhD-A + statisticus | H30: Te doen
A31: SOP-5 | B31: SEBIA — vijf stappen | C31: Stap 1 baseline, 2 op visite 2, 3 op maand 6 en 12, 4 op maand 9 en 15, 5 op maand 18 | D31: 2–4 | E31: okt – dec 26 | F31: D1.3 | G31: PhD-A + Dobbels | H31: Te doen
A32: SOP-6 | B32: Ulcusdetectie en documentatie | C32: Zie taak 1.4 | D32: 2 | E32: okt 26 | F32: D1.4 | G32: PhD-A + arts | H32: Te doen
A33: SOP-7 | B33: Randomisatie en blindering | C33: Identieke enveloppen, door elkaar gestoken; openen pas na geschiktheid, toestemming en baselinemetingen; documenteren met datum, uur en code | D33: 3 | E33: nov 26 | F33: D1.3 | G33: PhD-A+ Deschamps | H33: Te doen | I33: Methode nog nergens beschreven — punt 2
A34: SOP-8 | B34: Databeheer en monitoring | C34: Rollen, wekelijks querymanagement, afwijkingenlog, dagelijkse back-up, risicogebaseerd monitoringplan | D34: 3–4 | E34: nov – dec 26 | F34: D1.3 | G34: PhD-A + Deschamps | H34: Te doen
A35: Taak 1.4 — Ulcusprotocol · M1–5 · D1.4 · draagt het primaire eindpunt
A36: 1.4a | B36: Definitie en afbakening | C36: IWGDF-definitie; wrijvingsletsels aan laterale of dorsale voet binnen drie weken na nieuw schoeisel tellen niet mee | D36: 1–2 | E36: sep – okt 26 | F36: D1.4 | G36: PhD-A + arts+ Deschamps | H36: Te doen
A37: 1.4b | B37: Meldings- en documentatieroute | C37: Onmiddellijk aan de investigator; foto's, debridement, PEDIS en WIfI; geanonimiseerd naar een beveiligd platform | D37: 2 | E37: okt 26 | F37: D1.4 | G37: PhD-A | H37: Te doen | I37: ManGO
A38: 1.4c | B38: Fotoplatform regelen | C38: Keuze, gegevensbeschermingsbeoordeling, één aangeduide arts per centrum, één testcasus doorlopen | D38: 2 | E38: okt 26 | F38: D1.4 | G38: PhD-A + DPO | H38: Te doen | I38: Langste doorlooptijd buiten eigen controle
A39: 1.4d | B39: Beslissen wie het ulcus vaststelt | C39: Onafhankelijke geblindeerde commissie, of het multidisciplinaire team dat nu in het manuscript staat | D39: 1 | E39: sep 26 | F39: D1.4 | G39: Deschamps + PhD-A | H39: Te doen | I39: Openstaand punt 1 — eerst doen
A40: 1.4e | B40: AE- en SAE-procedure | C40: Registratie bij elke visite; sponsor binnen 72 u, EC en FAGG binnen 7 of 15 dagen | D40: 2 | E40: okt 26 | F40: D1.4 | G40: PhD-A | H40: Klaar
A41: Parallel — drie sporen zonder taaknummer, wel in de Go-criteria
...

Sheet Openstaande punten
A1: Openstaande punten
A2: Vijfentwintig punten, geordend naar wat ze vragen. Nagelopen tegen de bestanden op 10 september 2026.
A4: Nr | B4: Punt | C4: Wat er moet gebeuren | D4: Waar | E4: Prioriteit | F4: Status | G4: Opmerking
A5: A — Tegenstrijdig binnen het manuscript
A6: 1 | B6: Wie het ulcus vaststelt | C6: Beslist: het multidisciplinaire team, zoals de diagnose in de praktijk gesteld wordt. Er komt geen onafhankelijke geblindeerde adjudicatiecommissie. Zes plaatsen gelijkgezet: methodesectie (stond al goed), Strengths, Limitations, tabel 2 en de statistieksectie. In de Limitations staat het ontbreken van geblindeerde adjudicatie nu zelf als beperking. | D6: Methods, Strengths, Limitations, tabel 3, statistiek, SPIRIT 3d en 24c | E6: Hoog | F6: Klaar | G6: Beslissing PI 14 sep
A7: 2 | B7: Randomisatiemethode | C7: Gedaan: de methodesectie beschrijft nu hoe de volgorde tot stand komt (SPIRIT 16a) - 24 toewijzingen per centrum, 12 per arm, in identieke ondoorzichtige enveloppen, samen geschud en pas daarna genummerd, geen blokschema - met de voorspelbaarheid tegen het einde van een centrum er eerlijk bij. 'Variable permuted blocks' is uit het onderschrift van figuur 1. | D7: Methods, onderschrift figuur 1 | E7: Hoog | F7: Klaar | G7: Afgewerkt 14 sep
A8: 3 | B8: Doelstelling en hypothesen | C8: Gedaan: Objectives noemt een primair doel (ulcusrecidief over 18 maanden) met therapietrouw als vooraf vastgelegde mediator, primair geanalyseerd op 12 maanden. Hypotheses is teruggebracht tot een hypothese, met de mediator erbij en zonder eigen succescriterium. | D8: Objectives, Hypotheses | E8: Hoog | F8: Klaar | G8: Afgewerkt 14 sep
A9: 4 | B9: Wat Optimal Care omvat | C9: De labels '(Optimal Care)' uit tabel 2 halen bij voorschrift en aflevering van de CMFO | D9: Tabel 2 | E9: Middel | F9: Klaar | G9: Titel van tabel 4 is al rechtgezet
A10: 5 | B10: Drukmeting op visite 2 | C10: Gedaan: de drukmeting is aangevinkt op V2 in tabel 2 van het manuscript. De aparte visite 0 in het protocoldocument is NIET gedaan: dat vraagt een extra kolom in het SPIRIT-schema en een ingreep in Protocol_PARADISE_17_05_2026.docx. | D10: Tabel 2 | E10: Middel | F10: Bezig | G10: V2 gedaan 14 sep; visite 0 nog
A11: 6 | B11: Wie het ulcus vaststelt | C11: Beslist: het multidisciplinaire team, zoals de diagnose in de praktijk gesteld wordt. Er komt geen onafhankelijke geblindeerde adjudicatiecommissie. Zes plaatsen gelijkgezet: methodesectie (stond al goed), Strengths, Limitations, tabel 2 en de statistieksectie. In de Limitations staat het ontbreken van geblindeerde adjudicatie nu zelf als beperking. | D11: Methods, Strengths, Limitations, tabel 3, statistiek, SPIRIT 3d en 24c | E11: Hoog | F11: Klaar | G11: Beslissing PI 14 sep
A12: B — Redactie en pakket · kan grotendeels vandaag
A13: 7 | B13: Figuur 3 en 5 zonder titel | C13: Titelregel en ondertitel toevoegen in de SVG, zoals figuur 1, 2 en 4 die hebben | D13: Figure3_logic_model.svg, Figure5_CPTS.svg | E13: Middel | F13: Klaar
A14: 8 | B14: Plaatsingsmarkeringen en verwijzingen | C14: Gedaan: markeringen toegevoegd voor figuur 1, 4 en 5; de dubbele markering voor tabel 2 verwijderd. Alle negen figuren en tabellen hebben er nu precies een. Bijlage 4 wordt aangehaald in de statistieksectie en figuur 5 in de exploratieve analyse. | D14: Lopende tekst | E14: Middel | F14: Klaar | G14: Afgewerkt 14 sep
A15: 9 | B15: Toekenningsbrief FWO | C15: Opvragen en toevoegen; bijlage 6 toont nu alleen de ingediende aanvraag | D15: Bijlage 6 | E15: Middel | F15: Te doen
A16: 10 | B16: eCRF 01 | C16: Gedaan: PEDIS graad 3 en immunosuppressieve therapie toegevoegd bij de exclusie (nu negen), stabiele vaatstatus toegevoegd bij de inclusie (nu zes), en '(niet de eerste metatarsaalkop)' vervangen door 'de eerste inbegrepen'. | D16: eCRF 01 | E16: Hoog | F16: Klaar | G16: Afgewerkt 14 sep
A17: 11 | B17: Scoreformulier slijtageschaal | C17: Ontbreekt, terwijl de meting op visite 2 en op maand 6, 12 en 18 gepland staat | D17: eCRF-set | E17: Middel | F17: Te doen
A18: 12 | B18: Werkinstructie pedar | C18: Gedaan: eCRF 09b bestaat, 18 hoofdstukken, 55 stappen, 17 figuren. Nog 7 openstaande punten achteraan het document. | D18: eCRF-set | E18: Hoog | F18: Klaar | G18: Afgewerkt 14 sep
A19: 13
A20: 14 | B20: Texas Wound Classification | C20: Zit niet meer in de eCRF-set en staat niet in het manuscript | D20: eCRF-set | E20: Laag | F20: Vervalt | G20: Opgelost
A21: 15 | B21: Formulierenroute | C21: Beslist: een centrale REDCap-databank. De centra vullen papieren bronformulieren in en het studieteam zet die centraal over; sitepersoneel voert zelf niets in en het papieren werkblad blijft als brondocument op de site. 'Academic staff' is uit het manuscript. | D21: Data collection | E21: Middel | F21: Klaar | G21: Beslissing PI 14 sep
A22: 16 | B22: Zeven blanco velden | C22: Drie ingevuld: belangenconflicten, auteursbijdragen (CRediT, door de auteurs te bevestigen) en dankwoord. Vier blijven open omdat ze informatie van buiten vragen: registratienummer en -datum bij ClinicalTrials.gov, de startdatum van de rekrutering en de herschrijfmarkering bij de ethiekgoedkeuring. | D22: Abstract, Trial status, Declarations | E22: Hoog | F22: Bezig | G22: 3 van 7 gedaan 14 sep
A23: C — Projectdocumenten · bijwerken bij de eerste voortgangsrapportage
A24: 17 | B24: Go-criterium 6 en 7 | C24: Gedaan: de ICC-drempel van 0,80 staat nu op de Novel pedar in plaats van de F-Scan GO, en de methodevergelijking is geen startvoorwaarde meer maar loopt parallel aan de trial. Van zeven Go-criteria blijven er zes over. | D24: Draaiboek fase 06 | E24: Middel | F24: Klaar | G24: Afgewerkt 14 sep
A25: 18 | B25: MS4, MS5 en MS6 | C25: Staan op M24 en M42; protocol en manuscript komen op M18 en M37 uit | D25: FWO-planning | E25: Laag | F25: Te doen | G25: Speling, geen probleem
A27: Nieuw op 11 september — zelf inpassen waar je ze wilt
B28: Blootsvoets of in-shoe — beslist | C28: Alles in-shoe, twee condities: zónder en mét de CMFO. De 25%-reductie rekent tegenover de meting zonder zool in dezelfde sessie, tot drie aanpassingen (beslissing 6 oktober; de vaste referentie van 22 september vervalt). Tabel 4 van het manuscript had het goed | D28: Manuscript, protocol | E28: — | F28: Klaar | G28: Beslissing PI 11 sep
B29: eCRF 09 bijwerken | C29: Gedaan: de inleiding beschrijft nu een in-shoe meting zonder de CMFO, in het schoeisel waarmee de deelnemer binnenkomt; beide voeten tegelijk opgenomen en per voet uitgelezen. De titel van tabel 1 zegt 'in het schoeisel zonder diabetische CMFO'. De acht regio's stonden er al goed in. | D29: eCRF 09 | E29: Hoog | F29: Klaar | G29: Afgewerkt 14 sep
B30: eCRF 24 bijwerken | C30: Gedaan op 14 september: de blootsvoetse conditie is uit het formulier, deel A1 (buitenschoeisel) is verwijderd, Tabel 3A heet weer Tabel 3. Wat nog moet: de regiotabellen van zes naar acht regio's per voet. | D30: eCRF 24 | E30: Hoog | F30: Bezig | G30: Deels gedaan 14 sep
B31: SOP-2 en opleidingsmodule 3 bijwerken | C31: Meetprotocol en training moeten de in-shoe condities beschrijven in plaats van een blootsvoetse meting | D31: SOP-2, module 3 | E31: Hoog | F31: Te doen | G31: Volgt uit de beslissing
B32: Referentie bij nieuw schoeisel beslissen | C32: Beantwoord: de meting zónder zool hoort bij elk meetmoment, dus er is geen oude referentie die kan verouderen | D32: eCRF 24, SOP-2 | E32: Middel | F32: Vervalt | G32: Opgelost door de beslissing
B33: Palet op 200 kPa zetten en verdelen | C33: Hoogste niveau op 200 kPa, het niveau van 220 eruit. Bewaren met 'Save custom set' en op alle zes de laptops laden, anders zijn de schermafbeeldingen onderling niet vergelijkbaar | D33: novel studio, zes centra | E33: Hoog | F33: Te doen | G33: Vervangt de segmentatie tot die er is
B34: eCRF-Excel: veld voor de schermafbeelding | C34: Gedaan: het blad 'Meting' van de Pressure Monitoring Tool heeft blok 4 voor de drie hoogste waarden met hun plaats en blok 6 voor de twee schermafbeeldingen, per conditie. | D34: eCRF 09, eCRF 24 | E34: Hoog | F34: Klaar | G34: Afgewerkt 14 sep
B35: Set Range toetsen in de droogloop | C35: Beantwoord: Set Range past alleen de grafiek aan — begin, eind en verschuiven — en rekent niets opnieuw. De getallen blijven over de hele opname. Frames weglaten kan alleen achteraf, met file master in de novel database. | D35: droogloop november | E35: — | F35: Klaar | G35: Beslissing PI 14 sep
B36: MVP-weergave kiezen voor de secundaire analyses | C36: Vervalt: de MVP-weergave is niet van belang voor de studie. De norm gaat op MPP. | D36: SAP, eCRF 24 | E36: Middel | F36: Vervalt | G36: Beslissing PI 14 sep
B37: Schoenmaat 46 en groter | C37: Wordt gemeten met YW (44/45); de zool vangt het maatverschil op. Geen ZW bijbestellen, schoenmaat is geen uitsluitingsgrond | D37: SOP 09b | E37: — | F37: Klaar | G37: Beslist 11 sep
B38: Novel database: route en beheer | C38: De meting start in de novel database (14 sep). De studiedatabank is beslist: één centrale REDCap, centraal ingevoerd vanaf papier. Voor de novel database zelf blijft open of elk centrum een lokale krijgt en hoe de metingen samenkomen. | D38: novel database | E38: Hoog | F38: Te doen | G38: REDCap beslist 14 sep; novel-archief nog open
B39: Masker met de acht regio's tekenen | C39: Met 'creation of any and percent masks' de acht protocolregio's als percent mask op een referentiezool zetten. Daarna rekent 'multimask evaluation' per meting en 'groupmask evaluation' over alle metingen de piekdruk per regio uit. Dit vervangt het aflezen op het palet als analysemethode. | D39: novel database | E39: Hoog | F39: Te doen | G39: Lost punt 26 op
... B59: Alinea 65 zei 'own baseline pressure' | C59: Gevonden bij het invoegen van het ontlastingscriterium: de sectie Tailoring and fidelity zei dat het ontlastingsdoel tegen de eigen baselinedruk ligt. Rechtgezet naar de meting zonder de zool, conform de beslissing van 11 september; op 22 september gepreciseerd tot de meting zonder zool op visite 2. | D59: Manuscript | E59: — | F59: Klaar | G59: Rechtgezet 14 sep

Sheet Go-NoGo
A1: Go/No-Go — maand 6
A2: Zeven criteria voor de Executive Board, plus de negen site-readinesscriteria per centrum.
A4: Nr | B4: Criterium | C4: Go-drempel | D4: Bewijsstuk | E4: Status | F4: Opmerking
A5: Zeven Go-criteria · Executive Board, maand 6, unanimiteit vereist
A6: 1 | B6: Ethische goedkeuringen | C6: Zeven op zeven — centraal, zes lokaal, plus de bevoegde autoriteit | D6: Goedkeuringsbrieven en registratienummers | E6: Bezig
A7: 2 | B7: Site readiness | C7: Zes op zes centra voldoen aan alle negen criteria | D7: Ingevulde checklists | E7: Te doen | F7: Zie hieronder
A8: 3 | B8: Databank operationeel | C8: Nul kritische bugs na acceptatietest, versie-locked | D8: Testrapport en versielog | E8: Te doen
A9: 4 | B9: Certificering zorgverleners | C9: Minstens twee per centrum, dus twaalf of meer | D9: Certificatenregister in de Trial Master File | E9: Te doen
A10: 5 | B10: Pilootrapport | C10: Nul onopgeloste kritische knelpunten | D10: Pilootrapport v1.0 | E10: Te doen
A11: 6 | B11: Meetbetrouwbaarheid | C11: ICC ≥ 0,80 in alle centra, of gepoold | D11: ICC-rapport | E11: Te doen | F11: Op welk toestel? — punt 22
A12: 7 | B12: Methodevergelijking | C12: Overeenstemmingsgrenzen gekwantificeerd | D12: Bland-Altman-rapport | E12: Te doen | F12: Geen startvoorwaarde meer — punt 22
A14: Site readiness — 10criteria, per centrum af te vinken
A15: Nr | B15: Site readiness — negen criteria per centrum | C15: Categorie | D15: UZ Leuven | E15: UZ Antwerpen | F15: UZ Gent | G15: AZORG | H15: AZ Sint-Jan | I15: AZ Groeninge | J15: Status | K15: Opmerking
A16: 1 | B16: Drukmeetsysteem operationeel, met kalibratietestrun | C16: Technologie | J16: Te doen
A17: 2 | B17: Minstens twee gecertificeerde zorgverleners | C17: Opleiding | J17: Te doen
A18: 3 | B18: Databankaccount actief, testlogin geslaagd | C18: Data | J18: Te doen
A19: 4 | B19: Lokale ethische goedkeuring ontvangen | C19: Ethiek | J19: Te doen
A20: 5 | B20: Orthotimer-sensoren, lezer en software aanwezig | C20: Technologie | J20: Te doen
A21: 6 | B21: MoveMonitor aanwezig, uitgifte- en retourprotocol bekend | C21: Technologie | J21: Te doen
A22: 7 | B22: Minstens tien sets van het assessment booklet | C22: Klinisch | J22: Te doen
A23: 8 | B23: Loopruimte van minstens tien meter | C23: Infrastructuur | J23: Te doen
A24: 9 | B24: Back-upzorgverlener met naam en contact | C24: Organisatie | J24: Te doen
A25: 10 | B25: Novel Pedar, database en software aanwezig | C25: Technologie | J25: Te doen

Sheet Mijlpalen
A1: Mijlpalen
A2: De zeven mijlpalen die aan werkpakket 1 hangen. MS7 en MS8 horen bij WP2 en WP3.
A4: MS | B4: Wat | C4: Uit taak | D4: FWO-planning | E4: Volgens protocol | F4: Status | G4: Opmerking
A5: MS1 | B5: Boekjes en protocollen gemaakt | C5: 1.2, 1.3 | D5: M6 · feb 27 | E5: idem | F5: Te doen
A6: MS2 | B6: Gunstige ethische beoordeling verkregen | C6: 1.1 | D6: M6 · feb 27 | E6: idem | F6: Te doen
A7: MS3 | B7: Piloot en dataverzameling geslaagd | C7: 1.5 | D7: M6 · feb 27 | E7: idem | F7: Te doen
A8: MS4 | B8: 144 gerekruteerd en gerandomiseerd | C8: 1.6 | D8: M24 · aug 28 | E8: M18 · feb 28 | F8: Te doen
A9: MS5 | B9: Optimal en Usual Care geleverd | C9: 1.7 | D9: M42 · feb 30 | E9: M37 · sep 29 | F9: Te doen
A10: MS6 | B10: Opvolgbeoordelingen afgerond | C10: 1.7 | D10: M42 · feb 30 | E10: M37 · sep 29 | F10: Te doen
A11: MS9 | B11: Rapport klinische effectiviteit | C11: 1.8 | D11: M48 · aug 30 | E11: idem | F11: Te doen
